<?xml version="1.0"?>
<robot xmlns:xacro="http://www.ros.org/wiki/xacro" name="ur5_arm">

  <!-- World link (fixed base) - renamed to arm_world to avoid conflicts -->
  <link name="arm_world" />

  <!-- Base Link -->
  <link name="base_link">
    <visual>
      <origin rpy="0 0 3.141592653589793" xyz="0 0 0" />
      <geometry>
        <mesh filename="package://car_description/meshes/base.dae" />
      </geometry>
      <material name="LightGrey">
        <color rgba="0.7 0.7 0.7 1.0" />
      </material>
    </visual>
    <collision>
      <origin rpy="0 0 3.141592653589793" xyz="0 0 0" />
      <geometry>
        <mesh filename="package://car_description/meshes/base.dae" />
      </geometry>
    </collision>
    <inertial>
      <mass value="4.0"/>
      <inertia ixx="0.1" ixy="0" ixz="0" iyy="0.1" iyz="0" izz="0.1"/>
    </inertial>
  </link>

  <link name="shoulder_link">
    <visual>
      <origin rpy="0 0 3.141592653589793" xyz="0 0 0" />
      <geometry>
        <mesh filename="package://car_description/meshes/shoulder.dae" />
      </geometry>
      <material name="LightGrey">
        <color rgba="0.7 0.7 0.7 1.0" />
      </material>
    </visual>
    <collision>
      <origin rpy="0 0 3.141592653589793" xyz="0 0 0" />
      <geometry>
        <mesh filename="package://car_description/meshes/shoulder.dae" />
      </geometry>
    </collision>
    <inertial>
      <mass value="3.7"/>
      <inertia ixx="0.01" ixy="0" ixz="0" iyy="0.01" iyz="0" izz="0.01"/>
    </inertial>
  </link>

  <link name="upper_arm_link">
    <visual>
      <origin rpy="1.5707963267948966 0 -1.5707963267948966" xyz="0 0 0.138" />
      <geometry>
        <mesh filename="package://car_description/meshes/upperarm.dae" />
      </geometry>
      <material name="LightGrey">
        <color rgba="0.7 0.7 0.7 1.0" />
      </material>
    </visual>
    <collision>
      <origin rpy="1.5707963267948966 0 -1.5707963267948966" xyz="0 0 0.138" />
      <geometry>
        <mesh filename="package://car_description/meshes/upperarm.dae" />
      </geometry>
    </collision>
    <inertial>
      <mass value="8.393"/>
      <inertia ixx="0.1" ixy="0" ixz="0" iyy="0.1" iyz="0" izz="0.1"/>
    </inertial>
  </link>

  <link name="forearm_link">
    <visual>
      <origin rpy="1.5707963267948966 0 -1.5707963267948966" xyz="0 0 0.007" />
      <geometry>
        <mesh filename="package://car_description/meshes/forearm.dae" />
      </geometry>
      <material name="LightGrey">
        <color rgba="0.7 0.7 0.7 1.0" />
      </material>
    </visual>
    <collision>
      <origin rpy="1.5707963267948966 0 -1.5707963267948966" xyz="0 0 0.007" />
      <geometry>
        <mesh filename="package://car_description/meshes/forearm.dae" />
      </geometry>
    </collision>
    <inertial>
      <mass value="2.275"/>
      <inertia ixx="0.05" ixy="0" ixz="0" iyy="0.05" iyz="0" izz="0.05"/>
    </inertial>
  </link>

  <link name="wrist_1_link">
    <visual>
      <origin rpy="1.5707963267948966 0 0" xyz="0 0 -0.127" />
      <geometry>
        <mesh filename="package://car_description/meshes/wrist1.dae" />
      </geometry>
      <material name="LightGrey">
        <color rgba="0.7 0.7 0.7 1.0" />
      </material>
    </visual>
    <collision>
      <origin rpy="1.5707963267948966 0 0" xyz="0 0 -0.127" />
      <geometry>
        <mesh filename="package://car_description/meshes/wrist1.dae" />
      </geometry>
    </collision>
    <inertial>
      <mass value="1.219"/>
      <inertia ixx="0.01" ixy="0" ixz="0" iyy="0.01" iyz="0" izz="0.01"/>
    </inertial>
  </link>

  <link name="wrist_2_link">
    <visual>
      <origin rpy="0 0 0" xyz="0 0 -0.0997" />
      <geometry>
        <mesh filename="package://car_description/meshes/wrist2.dae" />
      </geometry>
      <material name="LightGrey">
        <color rgba="0.7 0.7 0.7 1.0" />
      </material>
    </visual>
    <collision>
      <origin rpy="0 0 0" xyz="0 0 -0.0997" />
      <geometry>
        <mesh filename="package://car_description/meshes/wrist2.dae" />
      </geometry>
    </collision>
    <inertial>
      <mass value="1.219"/>
      <inertia ixx="0.01" ixy="0" ixz="0" iyy="0.01" iyz="0" izz="0.01"/>
    </inertial>
  </link>
  
  <link name="wrist_3_link">
    <visual>
      <origin rpy="1.5707963267948966 0 0" xyz="0 0 -0.0989" />
      <geometry>
        <mesh filename="package://car_description/meshes/wrist3.dae" />
      </geometry>
      <material name="LightGrey">
        <color rgba="0.7 0.7 0.7 1.0" />
      </material>
    </visual>
    <collision>
      <origin rpy="1.5707963267948966 0 0" xyz="0 0 -0.0989" />
      <geometry>
        <mesh filename="package://car_description/meshes/wrist3.dae" />
      </geometry>
    </collision>
    <inertial>
      <mass value="0.1879"/>
      <inertia ixx="0.001" ixy="0" ixz="0" iyy="0.001" iyz="0" izz="0.001"/>
    </inertial>
  </link>

  <!-- Joints -->
  <!-- Base joint fixed to arm_world -->
  <joint name="base_fixed_joint" type="fixed">
    <parent link="arm_world"/>
    <child link="base_link"/>
    <origin xyz="3 0 0.075" rpy="0 0 0"/>
  </joint>

  <joint name="joint_1" type="revolute">
    <parent link="base_link" />
    <child link="shoulder_link" />
    <origin rpy="0 0 0" xyz="0 0 0.1625" />
    <axis xyz="0 0 1" />
    <limit effort="150.0" lower="-6.283185307179586" upper="6.283185307179586" velocity="3.141592653589793" />
  </joint>

  <joint name="joint_2" type="revolute">
    <parent link="shoulder_link" />
    <child link="upper_arm_link" />
    <origin rpy="1.5707 1.5707 0" xyz="0 0 0" />
    <axis xyz="0 0 1" />
    <limit effort="150.0" lower="-6.283185307179586" upper="6.283185307179586" velocity="3.141592653589793" />
  </joint>

  <joint name="joint_3" type="revolute">
    <parent link="upper_arm_link" />
    <child link="forearm_link" />
    <origin rpy="0 0 0" xyz="-0.425 0 0" />
    <axis xyz="0 0 1" />
    <limit effort="150.0" lower="-3.141592653589793" upper="3.141592653589793" velocity="3.141592653589793" />
  </joint>

  <joint name="joint_4" type="revolute">
    <parent link="forearm_link" />
    <child link="wrist_1_link" />
    <origin rpy="0 0 -1.5707" xyz="-0.3922 0 0.1333" />
    <axis xyz="0 0 1" />
    <limit effort="28.0" lower="-6.283185307179586" upper="6.283185307179586" velocity="3.141592653589793" />
  </joint>

  <joint name="joint_5" type="revolute">
    <parent link="wrist_1_link" />
    <child link="wrist_2_link" />
    <origin rpy="1.570796327 0 0" xyz="0 -0.0997 0" />
    <axis xyz="0 0 1" />
    <limit effort="28.0" lower="-6.283185307179586" upper="6.283185307179586" velocity="3.141592653589793" />
  </joint>

  <joint name="joint_6" type="revolute">
    <parent link="wrist_2_link" />
    <child link="wrist_3_link" />
    <origin rpy="1.570796326589793 3.141592653589793 3.141592653589793" xyz="0 0.0996 0" />
    <axis xyz="0 0 1" />
    <limit effort="28.0" lower="-6.283185307179586" upper="6.283185307179586" velocity="3.141592653589793" />
  </joint>

  <!-- Gazebo properties for the arm -->
  <gazebo reference="base_link">
    <material>Gazebo/LightGrey</material>
    <static>false</static>
  </gazebo>
  
  <gazebo reference="shoulder_link">
    <material>Gazebo/LightGrey</material>
  </gazebo>
  
  <gazebo reference="upper_arm_link">
    <material>Gazebo/LightGrey</material>
  </gazebo>
  
  <gazebo reference="forearm_link">
    <material>Gazebo/LightGrey</material>
  </gazebo>
  
  <gazebo reference="wrist_1_link">
    <material>Gazebo/LightGrey</material>
  </gazebo>
  
  <gazebo reference="wrist_2_link">
    <material>Gazebo/LightGrey</material>
  </gazebo>
  
  <gazebo reference="wrist_3_link">
    <material>Gazebo/LightGrey</material>
  </gazebo>

</robot>
